Workbook

Sheet DICCIONARIO
A1: Nombre columna | B1: Hoja origen | C1: Descripción | D1: Tipo de dato | E1: Valores posibles / Ejemplo | F1: Reglas de llenado | G1: Edición restringida | H1: Validaciones | I1: Origen / Relación con otra hoja | J1: Observaciones
A2: ContenidoID | B2: CONTENIDOS_PRODUCIDOS | C2: Identificador único asignado a cada contenido producido en el sistema. Permite diferenciarlo, relacionarlo con otros registros y evitar duplicidades. | D2: Texto alfanumérico único, sin repetir (se autocompleta) | E2: CONT1, CONT2, CONT3 | F2: Se completa automáticamente por script al ingresar el Título | G2: Solo editable por script; no se permite edición manual. | H2: Valor único, no permite duplicados. Generado automáticamente.
A3: Titulo | B3: CONTENIDOS_PRODUCIDOS | C3: Nombre principal del contenido. Debe ser claro y conciso, representando de manera directa lo que el contenido ofrece o aborda. | D3: Texto | E3: Ejemplo: "Gráficos cartesianos", "Estadística" | F3: Obligatorio | G3: Área responsable de la carga. (GOICE) | H3: Campo de texto. No permite valores vacíos.
A4: Descripcion | B4: CONTENIDOS_PRODUCIDOS | C4: Resumen explicativo del contenido. Detalla temática, objetivos, puntos centrales y palabras clave asociadas. Permite que otros usuarios lo identifiquen fácilmente y comprendan su utilidad. | D4: Texto largo | E4: Ejemplo: "Secuencia didáctica sobre energías renovables para secundaria”; “Juego interactivo para practicar suma y resta de fracciones". | F4: Obligatorio. Incluir tema, objetivo y palabras clave | G4: Área responsable de la carga. (GOICE) | H4: Campo de texto largo. No permite valores vacíos.
A5: TipoContenido_Nombre | B5: CONTENIDOS_PRODUCIDOS | C5: Clasificación del contenido según su naturaleza y formato. Se selecciona de una lista predefinida y ayuda a organizar, filtrar y buscar materiales similares. | D5: Selección desplegable (texto) | E5: Valores posibles: Módulo, Módulo Interactivo, Juego educativo, Infografía interactiva, Microcontenido, Evaluación formativa, Contenido Curricular, Secuencia Didáctica, Recurso Interactivo, Video, Texto, Actividad Integradora, Cuestionario, Prueba, Curso, Unidad | F5: Obligatorio. Seleccionar del desplegable. | G5: Área responsable de la carga. (GOICE) | H5: Lista desplegable desde la hoja TIPO_CONTENIDO. Solo permite valores de la lista. | I5: TIPO_CONTENIDO | J5: Si el tipo de contenido que necesitás no aparece en el desplegable, solicitá su incorporación en la hoja TIPO_CONTENIDO.
A6: TipoContenidoID | B6: CONTENIDOS_PRODUCIDOS | C6: Código identificador del tipo de contenido. Se genera o completa automáticamente al seleccionar el nombre de tipo y sirve para establecer relaciones técnicas entre registros. | D6: Texto alfanumérico (se autocompleta) | E6: Ejemplo: TCON1, TCON2, TCON3 | F6: Se autocompleta. No editar manualmente. | G6: Solo editable por sistema/autocompletado. | H6: Autocompletado por fórmula desde TIPO_CONTENIDO según TipoContenido_Nombre. | I6: TIPO_CONTENIDO | J6: No editar manualmente. Si hay inconsistencias, revisar la hoja TIPO_CONTENIDO.
A7: Nombre_proveedor | B7: CONTENIDOS_PRODUCIDOS | C7: Nombre de la persona, empresa, equipo o área que desarrolló o brindó el contenido. Se elige desde un listado ya existente para garantizar precisión y facilitar búsqueda por proveedor. | D7: Selección desplegable (texto) | E7: Ejemplo: Khan Academy, Ticmas | F7: Obligatorio. Seleccionar del desplegable. | G7: Área responsable de la carga. (GOICE) | H7: Lista desplegable desde la hoja PROVEEDORES. Solo permite valores de la lista. | I7: PROVEEDORES | J7: Si el proveedor no figura en el desplegable, solicitá su alta en la hoja PROVEEDORES antes de continuar.
A8: ProveedorID | B8: CONTENIDOS_PRODUCIDOS | C8: Código único que identifica al proveedor. Se autocompleta al elegir el nombre del proveedor y permite relacionar el contenido con información ampliada del proveedor en la base de datos. | D8: Texto alfanumérico (se autocompleta) | E8: Ejemplo: PROV1, PROV2, PROV3 | F8: Se autocompleta. No editar manualmente. | G8: Solo editable por sistema/autocompletado. | H8: Autocompletado por fórmula desde PROVEEDORES según Nombre_proveedor. | I8: PROVEEDORES | J8: No editar manualmente. Si hay inconsistencias, revisar la hoja PROVEEDORES.
A9: URL_Contenido | B9: CONTENIDOS_PRODUCIDOS | C9: Enlace directo en internet donde puede consultarse, visualizarse o descargarse el contenido. Permite acceder rápidamente al material desde la base de datos. | D9: URL (texto) | E9: Ejemplo: https://rise.articulate.com/share/agPj3vmKBvLlcQys3ZdJxRGrNN9ZagD4 | F9: Obligatorio para contenidos digitales. Formato URL válida. | G9: Área responsable de la carga. (GOICE) | H9: Formato URL válida (debe comenzar con http:// o https://).
A10: Licencia | B10: CONTENIDOS_PRODUCIDOS | C10: Tipo de permiso o autorización bajo la que puede utilizarse el contenido: puede ser libre, restringida, educativa, etc. Brinda claridad sobre el uso permitido y las condiciones legales. | D10: Selección desplegable o texto breve | E10: Valores posibles/ejemplo: Creative Commons, Licencia educativa, Copyright institucional | F10: Opcional. Completar si corresponde. | G10: Área responsable de la carga. (GOICE) | H10: Campo de texto o lista desplegable según valores predefinidos. Permite vacío.
A11: Modalidad_Tipo | B11: CONTENIDOS_PRODUCIDOS | C11: Conjunto de modalidades educativas asociadas al contenido. Puede incluir una o varias opciones entre Bachiller Común A, Bachiller Común B y Técnica. Los valores disponibles provienen de la hoja MODALIDADES. La selección de modalidad habilita la elección de espacios curriculares vinculados en la columna siguiente. | D11: Selección desplegable múltiple (texto) | E11: Valores posibles: Bachiller Común A, Bachiller Común B, Técnica (pueden seleccionarse uno o varios a la vez) | F11: Obligatorio. Seleccionar una o más opciones. Habilita la columna siguiente. | G11: Área responsable de la carga. (GOICE) | H11: Lista desplegable múltiple desde la hoja MODALIDADES. Permite selección múltiple. | I11: MODALIDADES | J11: Si necesitás agregar una nueva modalidad, solicitá su incorporación en la hoja MODALIDADES.
A12: Nombre_Espacio_curricular | B12: CONTENIDOS_PRODUCIDOS | C12: Denominación del espacio curricular (materia) correspondiente según la modalidad educativa seleccionada. Los valores disponibles se obtienen de la hoja ESPACIOS_CURRICULARES. | D12: Selección desplegable (texto) | E12: Ejemplo: Matemática, Lengua y Literatura, Física, Historia, Inglés | F12: Obligatorio. Se habilita tras seleccionar Modalidad_Tipo. | G12: Área responsable de la carga. (GOICE) | H12: Lista desplegable desde la hoja ESPACIO_CURRICULAR_SA, filtrada según Modalidad_Tipo seleccionada. | I12: ESPACIO_CURRICULAR_SA | J12: Si el espacio curricular no aparece en el desplegable según la modalidad elegida, solicitá su incorporación en la hoja ESPACIO_CURRICULAR_SA. Importante: El desplegable se genera automáticamente según la modalidad seleccionada. Si el desplegable no aparece de inmediato, no escriban el valor manualmente. Esperen unos segundos o cambien de celda y vuelvan a seleccionarla.
A13: ID_Espacio_curricular | B13: CONTENIDOS_PRODUCIDOS | C13: Identificador único asociado al espacio curricular seleccionado. Se autocompleta al elegir el nombre y se relaciona con la hoja ESPACIOS_CURRICULARES. | D13: Texto alfanumérico (se autocompleta) | E13: Ejemplo: ECURR1, ECURR2, ECURR3 | F13: Se autocompleta. No editar manualmente. | G13: Solo editable por sistema/autocompletado. | H13: Autocompletado por fórmula desde ESPACIO_CURRICULAR_SA según Nombre_Espacio_curricular. | I13: ESPACIO_CURRICULAR_SA | J13: No editar manualmente. Si hay inconsistencias, revisar la hoja ESPACIO_CURRICULAR_SA.
A14: Bimestre_Aplicacion | B14: CONTENIDOS_PRODUCIDOS | C14: Periodo del año escolar en el que está previsto implementar el contenido. Suele referirse a uno de los bimestres o etapas definidas en el calendario académico. | D14: Selección múltiple desplegable (texto) | E14: Valores posibles: 1, 2, 3, 4, Anual | F14: Obligatorio. Indicar período escolar. | G14: Área responsable de la carga. (GOICE) | H14: Lista desplegable con valores predefinidos. Solo permite valores de la lista.
A15: Link_contenido_priorizado | B15: CONTENIDOS_PRODUCIDOS | C15: Enlace al documento curricular oficial donde se detallan los contenidos priorizados para el espacio curricular correspondiente. Este documento es la referencia que se utilizó para orientar la producción del contenido. | D15: URL (texto) | E15: Ejemplo: https://buenosaires.gob.ar/sites/default/files/2025-08/CONTENIDOS_PRIORIZADOS_FG.pdf | F15: Obligatorio si existe documento de contenidos priorizados para el espacio curricular. Debe completarse con un enlace válido. | G15: Área responsable de la carga. (GOICE) | H15: Formato URL válida, debe empezar con http:// o https://
A16: Destinatario | B16: CONTENIDOS_PRODUCIDOS | C16: Grupo o colectivo principal al que va dirigido el contenido. Los valores posibles incluyen alumnos, docentes y familias. Las opciones provienen de una lista predefinida. | D16: Selección desplegable (texto) | E16: Valores posibles: Alumnos, Docentes, Familias | F16: Obligatorio. Seleccionar del desplegable. | G16: Área responsable de la carga. (GOICE) | H16: Lista desplegable con valores: Alumnos, Docentes, Familias. Solo permite valores de la lista.
A17: Estado_Revision | B17: CONTENIDOS_PRODUCIDOS | C17: Estado actual del proceso de revisión del contenido, según las opciones establecidas en una lista desplegable. Permite conocer el avance y seguimiento de validaciones. | D17: Selección desplegable (texto) | E17: Valores posibles/ejemplo: En revisión, Aprobado, Requiere ajustes, No aprobado | F17: Obligatorio. Seleccionar del desplegable. | G17: Área responsable de la carga. (GOICE) | H17: Lista desplegable con valores predefinidos de estados de revisión. Solo permite valores de la lista.
A18: Area_ministerio_revisor | B18: CONTENIDOS_PRODUCIDOS | C18: Nombre del área ministerial responsable por la revisión del contenido. Identifica la dirección, gerencia o sector que realizó la validación. Las opciones provienen de una lista predefinida. | D18: Selección desplegable (texto) | E18: Ejemplo: GOICE - Gerencia Operativa de Innovación y Contenidos Educativos | F18: Obligatorio si el contenido fue revisado. | G18: Área responsable de la carga. (GOICE) | H18: Campo de texto o lista desplegable según áreas ministeriales registradas.
A19: Apellidos_nombres_revisor | B19: CONTENIDOS_PRODUCIDOS | C19: Identificación del responsable de la revisión a través de apellido y nombre. Los valores se seleccionan de un desplegable alimentado por la hoja ACTORES, la cual debe estar previamente completada con las personas habilitadas para la revisión. | D19: Selección desplegable (texto) | E19: Ejemplo: García, Ana; López, María del Carmen; Pérez, Juan | F19: Obligatorio si el contenido fue revisado. Seleccionar del desplegable. | G19: Área responsable de la carga. (GOICE) | H19: Lista desplegable desde la hoja ACTORES. Solo permite valores de la lista. | I19: ACTORES | J19: Si el revisor no figura en el desplegable, solicitá su alta en la hoja ACTORES.
A20: Actor_ID | B20: CONTENIDOS_PRODUCIDOS | C20: Código único vinculado al revisor seleccionado. Se autocompleta a partir de la selección de Apellidos_nombres_revisor y de la hoja donde figuran los revisores. | D20: Texto alfanumérico (se autocompleta) | E20: Ejemplo: ACT1, ACT2, ACT3 | F20: Se autocompleta. No editar manualmente. | G20: Solo editable por sistema/autocompletado. | H20: Autocompletado por fórmula desde ACTORES según Apellidos_nombres_revisor. | I20: ACTORES | J20: No editar manualmente. Si hay inconsistencias, revisar la hoja ACTORES.
A21: Fecha_Revision | B21: CONTENIDOS_PRODUCIDOS | C21: Fecha en que se realizó la última revisión del contenido. Debe actualizarse cada vez que se modifica el estado de revisión. | D21: Fecha (formato fecha válida) | E21: Ejemplo: 20/10/2025 | F21: Obligatorio al cambiar Estado_Revision. Formato dd/mm/aaaa. | G21: Área responsable de la carga. (GOICE y GOED) | H21: Formato fecha válida (dd/mm/aaaa). No permite fechas futuras o valores de texto.
A22: Calificacion_Calidad | B22: CONTENIDOS_PRODUCIDOS | C22: Valoración asignada a la calidad del contenido tras la revisión, según criterios internos. Se selecciona entre opciones predefinidas en una lista desplegable. | D22: Selección desplegable (texto) | E22: Valores posibles/ejemplo: Alta, Media, Baja; Excelente, Satisfactorio, Insuficiente | F22: Obligatorio tras revisión. Seleccionar del desplegable. | G22: Área responsable de la carga. (GOICE) | H22: Lista desplegable con valores predefinidos de calificación. Solo permite valores de la lista.
A23: Vigencia_Desde | B23: CONTENIDOS_PRODUCIDOS | C23: Fecha a partir de la cual el contenido puede ser publicado, distribuido o utilizado oficialmente. Permite establecer desde cuándo está vigente su uso. | D23: Fecha (formato fecha válida) | E23: Ejemplo: 20/10/2025 | F23: Obligatorio. Formato dd/mm/aaaa. | G23: Área responsable de la carga. (GOICE) | H23: Formato fecha válida (dd/mm/aaaa). No permite valores de texto.
A24: Vigencia_Hasta | B24: CONTENIDOS_PRODUCIDOS | C24: Fecha límite hasta la que el contenido mantiene su validez para ser utilizado, consultado o distribuido. Tras esta fecha puede considerarse obsoleto o necesitar revisión | D24: Fecha (formato fecha válida) | E24: Ejemplo: 20/10/2025 | F24: Opcional. Formato dd/mm/aaaa. | G24: Área responsable de la carga. (GOICE) | H24: Formato fecha válida (dd/mm/aaaa). Debe ser posterior a Vigencia_Desde si se completa.
A25: Estado | B25: CONTENIDOS_PRODUCIDOS | C25: Situación actual del contenido dentro del sistema. Los valores posibles incluyen, entre otros: Activo, En desarrollo, Pendiente, Suspendido, Inactivo y Obsoleto. Permite conocer de un vistazo si el contenido está disponible, en proceso o ya no debe utilizarse. Los valores se seleccionan de una lista desplegable predefinida. | D25: Selección desplegable (texto) | E25: Valores posibles/ejemplo: Alta, Media, Baja; Excelente, Satisfactorio, Insuficiente | F25: Obligatorio. Seleccionar del desplegable. | G25: Área responsable de la carga. (GOED) | H25: Lista desplegable con valores: Activo, En desarrollo, Pendiente, Suspendido, Inactivo, Obsoleto. Solo permite valores de la lista.

Sheet CONTENIDOS_PRODUCIDOS
A1: ContenidoID | B1: Titulo | C1: Descripcion | D1: TipoContenido_Nombre | E1: TipoContenidoID | F1: Nombre_proveedor | G1: ProveedorID | H1: URL_Contenido | I1: Licencia | J1: Modalidad_Tipo | K1: Nombre_Espacio_curricular | L1: ID_Espacio_curricular | M1: Bimestre_Aplicacion | N1: Link_contenido_priorizado | O1: Destinatario | P1: Estado_Revision | Q1: Area_ministerio_revisor | R1: Apellidos_nombres_revisor | S1: Actor_ID | T1: Fecha_Revision | U1: Calificacion_Calidad | V1: Vigencia_Desde | W1: Vigencia_Hasta | X1: Estado
A2: CONT1 | B2: Números naturales y números enteros | C2: Descripción contenido 1 | E2: {=IF(D2:D1000 = "", "", IFERROR( INDEX( TIPO_CONTENIDO!A$2:A$17, MATCH(D2:D1000, TIPO_CONTENIDO!B$2:B$17, 0) ) ,"") )} | F2: Ticmas | G2: {=IFERROR( IF(F2="","",INDEX(PROVEEDORES!$A$2:$A$11, MATCH(F2, PROVEEDORES!$B$2:$B$11, 0))) ,"")} -> PROV2 | H2: https://rise.articulate.com/share/agPj3vmKBvLlcQys3ZdJxRGrNN9ZagD4 | J2: Bachiller Común A | K2: Matemática I | L2: ECURR3 | M2: 1 | P2: Publicado | Q2: GOICE - Gerencia Operativa de Innovación y Contenidos Educativos | T2: 45950 | X2: En desarrollo
A3: CONT2 | B3: Gráficos cartesianos | C3: Descripción contenido 2 | F3: Ticmas | G3: {=IFERROR( IF(F3="","",INDEX(PROVEEDORES!$A$2:$A$11, MATCH(F3, PROVEEDORES!$B$2:$B$11, 0))) ,"")} -> PROV2 | H3: https://rise.articulate.com/share/M9udTVX6crIZIcStC_uEpHQWwpzRHtMt | J3: Bachiller Común A | K3: Matemática II | L3: ECURR12 | M3: 2
A4: CONT3 | B4: Triángulos | C4: Descripción contenido 3 | F4: Ticmas | G4: {=IFERROR( IF(F4="","",INDEX(PROVEEDORES!$A$2:$A$11, MATCH(F4, PROVEEDORES!$B$2:$B$11, 0))) ,"")} -> PROV2 | H4: https://rise.articulate.com/share/GUcJbej46s1ZA1FZTvkx9DQmg8RfyhBu | J4: Bachiller Común A | K4: Laboratorio Ciencias Naturales E + F | L4: ECURR60 | M4: 3
A5: CONT4 | B5: Estadística | C5: Descripción contenido 4 | F5: Ticmas | G5: {=IFERROR( IF(F5="","",INDEX(PROVEEDORES!$A$2:$A$11, MATCH(F5, PROVEEDORES!$B$2:$B$11, 0))) ,"")} -> PROV2 | H5: https://rise.articulate.com/share/RdMmbP1ee-UzvrizvIDQilT4XP0ZzD7Y | J5: Bachiller Común A | M5: 4
A6: CONT5 | B6: Divisibilidad | F6: Ticmas | G6: {=IFERROR( IF(F6="","",INDEX(PROVEEDORES!$A$2:$A$11, MATCH(F6, PROVEEDORES!$B$2:$B$11, 0))) ,"")} -> PROV2 | H6: https://rise.articulate.com/share/dfqrz0psYSWFqsRPU9xlTkznSYpO8gOB | J6: Bachiller Común A | M6: 1
A7: CONT6 | B7: Función lineal | F7: Ticmas | G7: {=IFERROR(IF(F7="","",INDEX(PROVEEDORES!$A$2:$A$11, MATCH(F7, PROVEEDORES!$B$2:$B$11, 0))),"")} -> PROV2 | H7: https://rise.articulate.com/share/KEEpEeXkxXcuXtLeWXEW2QB_p3KAfW9z | M7: 2
A8: CONT7 | B8: Cuadriláteros y Teorema de Thales | F8: Ticmas | G8: {=IFERROR( IF(F8="","",INDEX(PROVEEDORES!$A$2:$A$11, MATCH(F8, PROVEEDORES!$B$2:$B$11, 0))) ,"")} -> PROV2 | H8: https://rise.articulate.com/share/B6m8OvP-au9QNFu6bOBsbdbnBZfgpHHv | M8: 3
A9: CONT8 | B9: Estadística | F9: Ticmas | G9: {=IFERROR( IF(F9="","",INDEX(PROVEEDORES!$A$2:$A$11, MATCH(F9, PROVEEDORES!$B$2:$B$11, 0))) ,"")} -> PROV2 | H9: https://rise.articulate.com/share/mmju6v4Q8k5X9AKjNJqqhXWdbGWYJ2g- | M9: 4
A10: CONT9 | B10: Problemas de conteo | F10: Ticmas | G10: {=IFERROR( IF(F10="","",INDEX(PROVEEDORES!$A$2:$A$11, MATCH(F10, PROVEEDORES!$B$2:$B$11, 0))) ,"")} -> PROV2 | H10: https://rise.articulate.com/share/wQPuomNeawd3pJRmOicTkpFlIHxRA6WZ | M10: 1
A11: CONT10 | B11: Sistema de ecuaciones | F11: Ticmas | G11: {=IFERROR( IF(F11="","",INDEX(PROVEEDORES!$A$2:$A$11, MATCH(F11, PROVEEDORES!$B$2:$B$11, 0))) ,"")} -> PROV2 | H11: https://rise.articulate.com/share/mg_wg364uyYU2ZCGqH0Fy0dQRUR5E_qL | M11: 2
A12: CONT11 | B12: Razones trigonométricas | F12: Ticmas | G12: {=IFERROR( IF(F12="","",INDEX(PROVEEDORES!$A$2:$A$11, MATCH(F12, PROVEEDORES!$B$2:$B$11, 0))) ,"")} -> PROV2 | H12: https://rise.articulate.com/share/m2KTACWWvrDbw2ZePqr7vwHcwsM1xzgj | M12: 3
A13: CONT12 | B13: Función cuadrática | F13: Ticmas | G13: {=IFERROR( IF(F13="","",INDEX(PROVEEDORES!$A$2:$A$11, MATCH(F13, PROVEEDORES!$B$2:$B$11, 0))) ,"")} -> PROV2 | H13: https://rise.articulate.com/share/eZUjzyVb2Cbo8Ru3oMH9c9AEU5-h4U1o | M13: 4
A14: CONT13 | B14: Errores en la medición. Sucesiones | F14: Ticmas | G14: {=IFERROR( IF(F14="","",INDEX(PROVEEDORES!$A$2:$A$11, MATCH(F14, PROVEEDORES!$B$2:$B$11, 0))) ,"")} -> PROV2 | H14: https://rise.articulate.com/share/o5gcsGusU5Iz-qcZL_VhetWxn_LJf2oZ | M14: 1
A15: CONT14 | B15: Funciones polinómicas | F15: Ticmas | G15: {=IFERROR( IF(F15="","",INDEX(PROVEEDORES!$A$2:$A$11, MATCH(F15, PROVEEDORES!$B$2:$B$11, 0))) ,"")} -> PROV2 | H15: https://rise.articulate.com/share/RVF7Uxu_yCsI638Z6aG7zlL2u7detRQZ | M15: 2
A16: CONT15 | B16: Funciones exponenciales y logarítmicas | F16: Ticmas | G16: {=IFERROR( IF(F16="","",INDEX(PROVEEDORES!$A$2:$A$11, MATCH(F16, PROVEEDORES!$B$2:$B$11, 0))) ,"")} -> PROV2 | H16: https://rise.articulate.com/share/4sz75xkf6tOHhhm2sjwe5zSNSmsRK6Ng | M16: 3
A17: CONT16 | B17: Probabilidad | F17: Ticmas | G17: {=IFERROR( IF(F17="","",INDEX(PROVEEDORES!$A$2:$A$11, MATCH(F17, PROVEEDORES!$B$2:$B$11, 0))) ,"")} -> PROV2 | H17: https://rise.articulate.com/share/ftavUKc1CDpY_IraL04bi8dZcdyU5dCx | M17: 4
A18: CONT17 | B18: Ecuaciones e inecuaciones | F18: Ticmas | G18: {=IFERROR( IF(F18="","",INDEX(PROVEEDORES!$A$2:$A$11, MATCH(F18, PROVEEDORES!$B$2:$B$11, 0))) ,"")} -> PROV2 | H18: https://rise.articulate.com/share/lH2-yrBVRRZN1tqArgi27zY5-MlpO5K7 | M18: 1
A19: CONT18 | B19: Funciones racionales | F19: Ticmas | G19: {=IFERROR( IF(F19="","",INDEX(PROVEEDORES!$A$2:$A$11, MATCH(F19, PROVEEDORES!$B$2:$B$11, 0))) ,"")} -> PROV2 | H19: https://rise.articulate.com/share/zcdgf7Whd61IbZeYpNXe6cBm-Yqp7rIT | M19: 2
... A41: CONT40 | B41: Leer, pensar y escribir en clave académica | F41: Ticmas | G41: {=IFERROR( IF(F41="","",INDEX(PROVEEDORES!$A$2:$A$11, MATCH(F41, PROVEEDORES!$B$2:$B$11, 0))) ,"")} -> PROV2 | H41: https://rise.articulate.com/share/VjplWy-rd3ooimV8iN4c2kNWU2LnZQbf | M41: 4
A42: CONT41 | B42: La vida escolar (1.1) | F42: Ticmas | G42: {=IFERROR( IF(F42="","",INDEX(PROVEEDORES!$A$2:$A$11, MATCH(F42, PROVEEDORES!$B$2:$B$11, 0))) ,"")} -> PROV2 | M42: 1
A43: CONT42 | B43: Conociéndonos y cuidando nuestro entorno (1.2) | F43: Ticmas | G43: {=IFERROR( IF(F43="","",INDEX(PROVEEDORES!$A$2:$A$11, MATCH(F43, PROVEEDORES!$B$2:$B$11, 0))) ,"")} -> PROV2 | M43: 2
A44: CONT43 | B44: Intereses personales y preferencias (1.3) | F44: Ticmas | G44: {=IFERROR( IF(F44="","",INDEX(PROVEEDORES!$A$2:$A$11, MATCH(F44, PROVEEDORES!$B$2:$B$11, 0))) ,"")} -> PROV2 | M44: 3
A45: CONT44 | B45: Cuidando el medio ambiente (1.4) | F45: Ticmas | G45: {=IFERROR( IF(F45="","",INDEX(PROVEEDORES!$A$2:$A$11, MATCH(F45, PROVEEDORES!$B$2:$B$11, 0))) ,"")} -> PROV2 | M45: 4
A46: CONT45 | B46: Hábitos alimenticios (2.1) | F46: Ticmas | G46: {=IFERROR( IF(F46="","",INDEX(PROVEEDORES!$A$2:$A$11, MATCH(F46, PROVEEDORES!$B$2:$B$11, 0))) ,"")} -> PROV2 | M46: 1
A47: CONT46 | B47: Historias y recuerdos (2.2) | F47: Ticmas | G47: {=IFERROR( IF(F47="","",INDEX(PROVEEDORES!$A$2:$A$11, MATCH(F47, PROVEEDORES!$B$2:$B$11, 0))) ,"")} -> PROV2 | M47: 2
A48: CONT47 | B48: Armar un presupuesto para una fiesta/evento (2.3) | F48: Ticmas | G48: {=IFERROR( IF(F48="","",INDEX(PROVEEDORES!$A$2:$A$11, MATCH(F48, PROVEEDORES!$B$2:$B$11, 0))) ,"")} -> PROV2 | M48: 3
A49: CONT48 | B49: Making a legendary event epic | F49: Ticmas | G49: {=IFERROR( IF(F49="","",INDEX(PROVEEDORES!$A$2:$A$11, MATCH(F49, PROVEEDORES!$B$2:$B$11, 0))) ,"")} -> PROV2 | M49: 4
A50: CONT49 | B50: Contar historias y compartir experiencias (3.1) | F50: Ticmas | G50: {=IFERROR( IF(F50="","",INDEX(PROVEEDORES!$A$2:$A$11, MATCH(F50, PROVEEDORES!$B$2:$B$11, 0))) ,"")} -> PROV2 | M50: 1
A51: CONT50 | B51: Compartir opiniones y dar consejos (3.2) | F51: Ticmas | G51: {=IFERROR( IF(F51="","",INDEX(PROVEEDORES!$A$2:$A$11, MATCH(F51, PROVEEDORES!$B$2:$B$11, 0))) ,"")} -> PROV2 | M51: 2
A52: CONT51 | B52: Argumentando nuestras ideas y valores (3.3) | F52: Ticmas | G52: {=IFERROR( IF(F52="","",INDEX(PROVEEDORES!$A$2:$A$11, MATCH(F52, PROVEEDORES!$B$2:$B$11, 0))) ,"")} -> PROV2 | M52: 3
A53: CONT52 | B53: Relate events in chronological order (3.4) | F53: Ticmas | G53: {=IFERROR( IF(F53="","",INDEX(PROVEEDORES!$A$2:$A$11, MATCH(F53, PROVEEDORES!$B$2:$B$11, 0))) ,"")} -> PROV2 | M53: 4
... A89: CONT88 | B89: Juger | F89: Ticmas | G89: {=IFERROR( IF(F89="","",INDEX(PROVEEDORES!$A$2:$A$11, MATCH(F89, PROVEEDORES!$B$2:$B$11, 0))) ,"")} -> PROV2 | M89: 4
A90: CONT89 | B90: Cómo llega el agua a mi vaso A | F90: Ticmas | G90: {=IFERROR( IF(F90="","",INDEX(PROVEEDORES!$A$2:$A$11, MATCH(F90, PROVEEDORES!$B$2:$B$11, 0))) ,"")} -> PROV2 | H90: https://rise.articulate.com/share/0oIju8xj659PHafjnvmpbkukc9IBtnIu | M90: 1
A91: CONT90 | B91: Cómo llega el agua a mi vaso B | F91: Ticmas | G91: {=IFERROR( IF(F91="","",INDEX(PROVEEDORES!$A$2:$A$11, MATCH(F91, PROVEEDORES!$B$2:$B$11, 0))) ,"")} -> PROV2 | H91: https://rise.articulate.com/share/yH8g84ssRUYCpkXv0qnzyGtKLVCRAEAC | M91: 2
A92: CONT91 | B92: ¿Por qué elegimos representantes en las urnas? A | F92: Ticmas | G92: {=IFERROR( IF(F92="","",INDEX(PROVEEDORES!$A$2:$A$11, MATCH(F92, PROVEEDORES!$B$2:$B$11, 0))) ,"")} -> PROV2 | H92: https://rise.articulate.com/share/Hvr9GswTOyVLFk9SdS0lhglSRsxV42yS | M92: 1
A93: CONT92 | B93: ¿Por qué elegimos representantes en las urnas? B | F93: Ticmas | G93: {=IFERROR( IF(F93="","",INDEX(PROVEEDORES!$A$2:$A$11, MATCH(F93, PROVEEDORES!$B$2:$B$11, 0))) ,"")} -> PROV2 | H93: https://rise.articulate.com/share/iuFmgScgObjuelZDY7s3OB4YTgwKMA37 | M93: 2
A94: CONT93 | B94: ¿Por qué Argentina es un país agroexportador? A | F94: Ticmas | G94: {=IFERROR( IF(F94="","",INDEX(PROVEEDORES!$A$2:$A$11, MATCH(F94, PROVEEDORES!$B$2:$B$11, 0))) ,"")} -> PROV2 | H94: https://rise.articulate.com/share/Nh4Bu82ZaVpso3lulj8BkFf0K46AT-Yb | M94: 1
A95: CONT94 | B95: ¿Por qué Argentina es un país agroexportador? B | F95: Ticmas | G95: {=IFERROR( IF(F95="","",INDEX(PROVEEDORES!$A$2:$A$11, MATCH(F95, PROVEEDORES!$B$2:$B$11, 0))) ,"")} -> PROV2 | H95: https://rise.articulate.com/share/MvBoY070U6OcuWJeQ99oQYg34O1EGxTO | M95: 2
A96: CONT95 | B96: ¿Cómo se produjo la globalización? A | F96: Ticmas | G96: {=IFERROR( IF(F96="","",INDEX(PROVEEDORES!$A$2:$A$11, MATCH(F96, PROVEEDORES!$B$2:$B$11, 0))) ,"")} -> PROV2 | H96: https://rise.articulate.com/share/NDSIanrX2M7zis7yqJimCyQgK46M2-nZ | M96: 1
...

Sheet ESPACIO_CURRICULAR_SA
A1: ID_Espacio_curricular | B1: Codigo_Espacio_curricular | C1: Modalidad | D1: Modalidad_Tipo | E1: CantidadEspecialidades | F1: Año/Nivel | G1: Nombre_Espacio_curricular | H1: EsCompuesta | I1: Activo | J1: CategoriaPCI | K1: MateriasAgrupadas | L1: CategoriaFormacion
A2: ECURR1 | B2: SA-BACHI-CS-SOCIALES-Y-H-1-LENGUA-ADICIONAL-I | C2: SA | D2: Bachiller Común A | E2: 16 | F2: Nivel 1 | G2: Lengua Adicional I | H2: FALSE | I2: TRUE | J2: Troncal | K2: Lengua adicional | L2: Formación General
A3: ECURR2 | B3: SA-BACHI-CS-SOCIALES-Y-H-1-LENGUA-Y-LITERATURA- | C3: SA | D3: Bachiller Común A | E3: 16 | F3: Nivel 1 | G3: Lengua y Literatura I | H3: FALSE | I3: TRUE | J3: Troncal | K3: Lengua y Literatura | L3: Formación Orientada
A4: ECURR3 | B4: SA-BACHI-CS-SOCIALES-Y-H-1-MATEM-TICA-I | C4: SA | D4: Bachiller Común A | E4: 16 | F4: Nivel 1 | G4: Matemática I | H4: FALSE | I4: TRUE | J4: Troncal | K4: Matemáticas | L4: Formación General
A5: ECURR48 | B5: SA-BACHI-CS-SOCIALES-Y-H-1-LABORATORIO-CIENCIAS | C5: SA | D5: Bachiller Común A | E5: 16 | F5: Nivel 1 | G5: Laboratorio Ciencias Naturales A + B | H5: FALSE | I5: TRUE | J5: Laboratorio | K5: Biología | L5: Formación Orientada
A6: ECURR49 | B6: SA-BACHI-CS-SOCIALES-Y-H-1-LABORATORIO-CIENCIAS | C6: SA | D6: Bachiller Común A | E6: 16 | F6: Nivel 1 | G6: Laboratorio Ciencias Sociales A + B | H6: TRUE | I6: TRUE | J6: Laboratorio | K6: Historia; Geografía; Formación ética y ciudadana | L6: Formación General
A7: ECURR81 | B7: SA-BACHI-CS-SOCIALES-Y-H-1-TALLER-DE-ARTES-A-B | C7: SA | D7: Bachiller Común A | E7: 16 | F7: Nivel 1 | G7: Taller de Artes A + B | H7: TRUE | I7: TRUE | J7: Taller | K7: Artes; EDI; Tutoría | L7: Formación General
A8: ECURR82 | B8: SA-BACHI-CS-SOCIALES-Y-H-1-TALLER-DE-EDUCAIC-N- | C8: SA | D8: Bachiller Común A | E8: 16 | F8: Nivel 1 | G8: Taller de Educaicón Física A + B | H8: FALSE | I8: TRUE | J8: Taller | K8: Educación física | L8: Formación General
A9: ECURR83 | B9: SA-BACHI-CS-SOCIALES-Y-H-1-TALLER-DE-TECNOLOG-A | C9: SA | D9: Bachiller Común A | E9: 16 | F9: Nivel 1 | G9: Taller de Tecnología A | H9: FALSE | I9: TRUE | J9: Taller | K9: Educación tecnológica | L9: Formación General
A10: ECURR10 | B10: SA-BACHI-CS-SOCIALES-Y-H-2-LENGUA-ADICIONAL-II | C10: SA | D10: Bachiller Común A | E10: 16 | F10: Nivel 2 | G10: Lengua Adicional II | H10: FALSE | I10: TRUE | J10: Troncal | K10: Lengua adicional | L10: Formación General
A11: ECURR11 | B11: SA-BACHI-CS-SOCIALES-Y-H-2-LENGUA-Y-LITERATURA- | C11: SA | D11: Bachiller Común A | E11: 16 | F11: Nivel 2 | G11: Lengua y Literatura II | H11: FALSE | I11: TRUE | J11: Troncal | K11: Lengua y Literatura | L11: Formación Orientada
A12: ECURR12 | B12: SA-BACHI-CS-SOCIALES-Y-H-2-MATEM-TICA-II | C12: SA | D12: Bachiller Común A | E12: 16 | F12: Nivel 2 | G12: Matemática II | H12: FALSE | I12: TRUE | J12: Troncal | K12: Matemáticas | L12: Formación General
A13: ECURR54 | B13: SA-BACHI-CS-SOCIALES-Y-H-2-LABORATORIO-CIENCIAS | C13: SA | D13: Bachiller Común A | E13: 16 | F13: Nivel 2 | G13: Laboratorio Ciencias Naturales C + D | H13: FALSE | I13: TRUE | J13: Laboratorio | K13: Biología | L13: Formación Orientada
... A127: ECURR126 | B127: SA-TÉCNI-T-CNICO-MEC-NIC-6-PROYECTO-DE-EGRESO | C127: SA | D127: Técnica | E127: 11 | F127: Nivel 6 | G127: PROYECTO DE EGRESO | H127: FALSE | I127: TRUE | J127: Otro | K127: Prácticas profesionalizantes | L127: Formación General

Sheet TIPO_CONTENIDO
A1: TipoContenidoID | B1: Nombre | C1: Descripción | D1: Ícono | E1: Activo
A2: {=IF( B2:B2005 = "", "", "TCON" & ROW(B2:B2005) - 1 )} -> TCON1 | B2: Módulo | C2: Conjunto de recursos o clases organizadas en torno a un tema o competencia específica. Generalmente parte de un curso más amplio. | D2: 📘 | E2: TRUE
A3: TCON2 | B3: Módulo Interactivo | C3: Versión digital de un módulo, con navegación autónoma y elementos interactivos (Rise, Genially, H5P, etc.). | D3: 💡 | E3: TRUE
A4: TCON3 | B4: Juego educativo | C4: Actividad lúdica con reglas, objetivos y retroalimentación, diseñada para reforzar aprendizajes mediante la gamificación. | D4: 🎮 | E4: TRUE
A5: TCON4 | B5: Infografía interactiva | C5: Representación visual con elementos dinámicos o clicables que explican un concepto, proceso o conjunto de datos | D5: 🧭 | E5: TRUE
A6: TCON5 | B6: Microcontenido | C6: Recurso breve y puntual (video corto, ficha, cápsula o animación) que aborda un concepto específico o una habilidad puntual. | D6: ⚡ | E6: TRUE
A7: TCON6 | B7: Evaluación formativa | C7: Instrumento o actividad de evaluación con retroalimentación inmediata, orientada al seguimiento del aprendizaje (no calificativa). | D7: 🧩 | E7: TRUE
A8: TCON7 | B8: Contenido Curricular | C8: Material que desarrolla los saberes y objetivos prescriptos en el currículo oficial. Base para la planificación docente. | D8: 🗂️ | E8: TRUE
A9: TCON8 | B9: Secuencia Didáctica | C9: Conjunto de actividades planificadas que articulan objetivos, contenidos y estrategias de enseñanza y evaluación. | D9: 🧱 | E9: TRUE
A10: TCON9 | B10: Recurso Interactivo | C10: Material digital que requiere acción del usuario (clics, elecciones, arrastres, etc.) para explorar un contenido o resolver desafíos. | D10: 🖱️ | E10: TRUE
A11: TCON10 | B11: Video | C11: Recurso audiovisual lineal (grabación, animación o screencast) con propósito explicativo, motivacional o demostrativo. | D11: ▶️ | E11: TRUE
A12: TCON11 | B12: Texto | C12: Documento escrito que transmite información conceptual o narrativa (guía, artículo, ficha de lectura, ensayo, etc.). | D12: 📝 | E12: TRUE
A13: TCON12 | B13: Actividad Integradora | C13: Propuesta de trabajo que articula varios saberes o competencias en torno a un problema o proyecto común. | D13: 🔄 | E13: TRUE
A14: TCON13 | B14: Cuestionario | C14: Conjunto estructurado de preguntas cerradas o abiertas para comprobar la comprensión o recoger opiniones. | D14: ❓ | E14: TRUE
... A17: TCON16 | B17: Unidad | C17: Segmento curricular dentro de un curso, con objetivos, contenidos y actividades centrados en un tema específico. | D17: 📄 | E17: TRUE

Sheet ACTORES
A1: ActorID | B1: Nombre | C1: Apellido | D1: Apellidos y nombres | E1: Email | F1: Telefono_celular | G1: NúmeroInterno | H1: Rol | I1: Area_Ministerio | J1: TipoArea | K1: Número de puesto | L1: Activo
A2: {=IF( B2:B2006 = "", "", "ACT" & ROW(B2:B2006) - 1 )} | D2: =IF(OR(B2="",C2=""),"",C2&", "&B2) | H2: Programador/a | I2: GOICE - Gerencia Operativa de Innovación y Contenidos Educativos | J2: Gerencia Operativa | L2: TRUE
D3: =IF(OR(B3="",C3=""),"",C3&", "&B3) | H3: Admintrador/a | I3: GOED - Gerencia Operativa de Educación Digital | J3: Gerencia Operativa | L3: TRUE
D4: =IF(OR(B4="",C4=""),"",C4&", "&B4) | H4: Diseñador/a | I4: GOED - Gerencia Operativa de Educación Digital | J4: Gerencia Operativa | L4: TRUE
D5: =IF(OR(B5="",C5=""),"",C5&", "&B5) | H5: Analista Datos | I5: GOED - Gerencia Operativa de Educación Digital | J5: Gerencia Operativa | L5: TRUE
D6: =IF(OR(B6="",C6=""),"",C6&", "&B6) | L6: TRUE
D7: =IF(OR(B7="",C7=""),"",C7&", "&B7) | L7: TRUE
D8: =IF(OR(B8="",C8=""),"",C8&", "&B8) | L8: TRUE
D9: =IF(OR(B9="",C9=""),"",C9&", "&B9) | L9: TRUE
D10: =IF(OR(B10="",C10=""),"",C10&", "&B10) | L10: TRUE
D11: =IF(OR(B11="",C11=""),"",C11&", "&B11) | L11: TRUE
D12: =IF(OR(B12="",C12=""),"",C12&", "&B12) | L12: TRUE
D13: =IF(OR(B13="",C13=""),"",C13&", "&B13) | L13: TRUE
D14: =IF(OR(B14="",C14=""),"",C14&", "&B14) | L14: TRUE
D15: =IF(OR(B15="",C15=""),"",C15&", "&B15) | L15: TRUE
D16: =IF(OR(B16="",C16=""),"",C16&", "&B16) | L16: TRUE
D17: =IF(OR(B17="",C17=""),"",C17&", "&B17) | L17: TRUE
... D20: =IF(OR(B20="",C20=""),"",C20&", "&B20) | L20: TRUE

Sheet TIPO_PROVEEDOR
A1: TipoProveedorID | B1: Nombre | C1: Descripcion | D1: Activo
A2: 1 | B2: Externo | C2: Tipo 1 | D2: TRUE
A3: 2 | B3: Ministerio | C3: Tipo 2 | D3: TRUE
A4: 3 | B4: ONG | C4: Tipo 3 | D4: TRUE
A5: 4 | B5: Universidad | C5: Tipo 4 | D5: TRUE
A6: 5 | B6: Editorial | C6: Tipo 5 | D6: TRUE

Sheet PROVEEDORES
A1: ProveedorID | B1: Nombre_proveedor | C1: Nombre_tipo_proveedor | D1: TipoProveedorID | E1: Contacto | F1: Email | G1: Nombre_referente | H1: Especialidades | I1: Estado | J1: Descripcion | K1: Activo
A2: {=IF( B2:B1000 = "", "", "PROV" & ROW(B2:B1000) - 1 )} -> PROV1 | B2: Khan Academy | C2: Externo | E2: Team | F2: contact@khan.org | H2: Matemática | I2: ACTIVO | J2: Plataforma global | K2: TRUE
A3: PROV2 | B3: Ticmas | C3: Externo | E3: Contenidos | F3: info@ticmas.com | H3: Todas | I3: ACTIVO | J3: Plataforma AR | K3: TRUE
A4: PROV3 | B4: Editorial XYZ | E4: Comercial | F4: ventas@xyz.com | H4: Ciencias | I4: ACTIVO | J4: Editorial tradicional | K4: TRUE

Sheet MODALIDADES
A1: ModalidadID | B1: Nombre | C1: Descripcion | D1: Años_Duracion | E1: Sistema_Evaluacion | F1: Periodos_Año | G1: Activo
A2: BACH1 | B2: Bachiller Común A | C2: Desc 1 | D2: 5 | E2: Bimestre | F2: 4 | G2: TRUE
A3: BACH2 | B3: Bachiller Común B | C3: Desc 2 | D3: 5 | E3: Bimestre | F3: 4 | G3: TRUE
A4: TEC3 | B4: Técnica | C4: Desc 3 | D4: 6 | E4: Bimestre | F4: 4 | G4: TRUE

Sheet ESPECIALIDADES
A1: EspecialidadID | B1: ModalidadID | C1: Nombre | D1: Codigo | E1: Area | F1: Tipo | G1: Activo
A2: {=IF( B2:B2000 = "", "", "ESP" & ROW(B2:B2000) - 1 )} -> ESP1 | B2: BACH1 | C2: CS. SOCIALES Y HUMANIDADES (alternativa A) | D2: ESP-001 | E2: General | F2: SA/NES | G2: TRUE
A3: ESP2 | B3: BACH1 | C3: ARTES VISUALES (alternativa A) | D3: ESP-002 | E3: General | F3: SA/NES | G3: TRUE
A4: ESP3 | B4: BACH1 | C4: ARTE MUSICA (alternativa A) | D4: ESP-003 | E4: General | F4: SA/NES | G4: TRUE
A5: ESP4 | B5: BACH1 | C5: ARTE TEATRO (alternativa A) | D5: ESP-004 | E5: General | F5: SA/NES | G5: TRUE
A6: ESP5 | B6: BACH1 | C6: CS. NATURALES (alternativa A) | D6: ESP-005 | E6: General | F6: SA/NES | G6: TRUE
A7: ESP6 | B7: BACH1 | C7: COMUNICACIÓN (alternativa A) | D7: ESP-006 | E7: General | F7: SA/NES | G7: TRUE
A8: ESP7 | B8: BACH1 | C8: ECONOMÍA Y ADMINISTRACIÓN (alternativa A) | D8: ESP-007 | E8: General | F8: SA/NES | G8: TRUE
A9: ESP8 | B9: BACH1 | C9: EDUCACIÓN (alternativa A) | D9: ESP-008 | E9: General | F9: SA/NES | G9: TRUE
A10: ESP9 | B10: BACH1 | C10: EDUCACIÓN FÍSICA (alternativa A) | D10: ESP-009 | E10: General | F10: SA/NES | G10: TRUE
A11: ESP10 | B11: BACH1 | C11: ENERGÍA Y SUSTENTABILIDAD (alternativa A) | D11: ESP-010 | E11: General | F11: SA/NES | G11: TRUE
A12: ESP11 | B12: BACH1 | C12: INFORMÁTICA (alternativa A) | D12: ESP-011 | E12: General | F12: SA/NES | G12: TRUE
A13: ESP12 | B13: BACH1 | C13: LENGUAS (alternativa A) | D13: ESP-012 | E13: General | F13: SA/NES | G13: TRUE
A14: ESP13 | B14: BACH1 | C14: LITERATURA (alternativa A) | D14: ESP-013 | E14: General | F14: SA/NES | G14: TRUE
... A44: ESP43 | B44: TEC3 | C44: Técnico en QUÍMICA | D44: ESP-043 | E44: General | F44: SA/NES | G44: TRUE

Sheet AÑOS_ACADEMICOS
A1: AnioID | B1: Numero | C1: Nombre | D1: Ciclo | E1: Descripcion | F1: Activo
A2: 1 | B2: 1 | C2: Primer Año | D2: Ciclo Básico | E2: Año 1 | F2: TRUE
A3: 2 | B3: 2 | C3: Segundo Año | D3: Ciclo Básico | E3: Año 2 | F3: TRUE
A4: 3 | B4: 3 | C4: Tercer Año | D4: Ciclo Básico | E4: Año 3 | F4: TRUE
A5: 4 | B5: 4 | C5: Cuarto Año | D5: Ciclo Orientado | E5: Año 4 | F5: TRUE
A6: 5 | B6: 5 | C6: Quinto Año | D6: Ciclo Orientado | E6: Año 5 | F6: TRUE
A7: 6 | B7: 6 | C7: Sexto Año | D7: Ciclo Orientado | E7: Año 6 | F7: TRUE

Sheet PERIODOS_ACADEMICOS
A1: PeriodoID | B1: Nombre | C1: Tipo | D1: Duracion_Semanas | E1: Cantidad_Anual | F1: Descripcion | G1: Activo
A2: 1 | B2: Bimestre | C2: Bimestral | D2: 8 | E2: 4 | F2: Período bimestral | G2: TRUE
A3: 2 | B3: Cuatrimestre | C3: Cuatrimestre | D3: 16 | E3: 2 | F3: Período cuatrimestral

Sheet MATERIAS_UNIFICADAS
A1: IDMateria | B1: CodigoMateria | C1: Modalidad | D1: Modalidad_Tipo | E1: EspecialidadID | F1: Año/Nivel | G1: NombreMateria | H1: EsCompuesta | I1: Activo | J1: CategoriaPCI | K1: MateriasAgrupadas | L1: CategoriaFormacion
A2: 1 | B2: NES-BACHI-CS-SOCIALES-Y-H-1-MATEM-TICAS | C2: NES | D2: Bachiller Común A | E2: CS. SOCIALES Y HUMANIDADES | F2: 1 | G2: Matemáticas | H2: FALSE | I2: TRUE | L2: Formación General
A3: 2 | B3: SA-BACHI-CS-SOCIALES-Y-H-1-MATEM-TICA-I | C3: SA | D3: Bachiller Común A | E3: CS. SOCIALES Y HUMANIDADES | F3: Nivel 1 | G3: Matemática I | H3: FALSE | I3: TRUE | J3: Troncal | K3: Matemáticas | L3: Formación General
A4: 3 | B4: NES-BACHI-ARTES-VISUALES-1-MATEM-TICAS | C4: NES | D4: Bachiller Común A | E4: ARTES VISUALES | F4: 1 | G4: Matemáticas | H4: FALSE | I4: TRUE | L4: Formación General
A5: 4 | B5: SA-BACHI-ARTES-VISUALES-1-MATEM-TICA-I | C5: SA | D5: Bachiller Común A | E5: ARTES VISUALES | F5: Nivel 1 | G5: Matemática I | H5: FALSE | I5: TRUE | J5: Troncal | K5: Matemáticas | L5: Formación General
A6: 5 | B6: NES-BACHI-ARTE-MUSICA-1-MATEM-TICAS | C6: NES | D6: Bachiller Común A | E6: ARTE MUSICA | F6: 1 | G6: Matemáticas | H6: FALSE | I6: TRUE | L6: Formación General
A7: 6 | B7: SA-BACHI-ARTE-MUSICA-1-MATEM-TICA-I | C7: SA | D7: Bachiller Común A | E7: ARTE MUSICA | F7: Nivel 1 | G7: Matemática I | H7: FALSE | I7: TRUE | J7: Troncal | K7: Matemáticas | L7: Formación General
A8: 7 | B8: NES-BACHI-ARTE-TEATRO-1-MATEM-TICAS | C8: NES | D8: Bachiller Común A | E8: ARTE TEATRO | F8: 1 | G8: Matemáticas | H8: FALSE | I8: TRUE | L8: Formación General
A9: 8 | B9: SA-BACHI-ARTE-TEATRO-1-MATEM-TICA-I | C9: SA | D9: Bachiller Común A | E9: ARTE TEATRO | F9: Nivel 1 | G9: Matemática I | H9: FALSE | I9: TRUE | J9: Troncal | K9: Matemáticas | L9: Formación General
A10: 9 | B10: NES-BACHI-CS-NATURALES-1-MATEM-TICAS | C10: NES | D10: Bachiller Común A | E10: CS. NATURALES | F10: 1 | G10: Matemáticas | H10: FALSE | I10: TRUE | L10: Formación General
A11: 10 | B11: SA-BACHI-CS-NATURALES-1-MATEM-TICA-I | C11: SA | D11: Bachiller Común A | E11: CS. NATURALES | F11: Nivel 1 | G11: Matemática I | H11: FALSE | I11: TRUE | J11: Troncal | K11: Matemáticas | L11: Formación General
A12: 11 | B12: NES-BACHI-COMUNICACI-N-1-MATEM-TICAS | C12: NES | D12: Bachiller Común A | E12: COMUNICACIÓN | F12: 1 | G12: Matemáticas | H12: FALSE | I12: TRUE | L12: Formación General
A13: 12 | B13: SA-BACHI-COMUNICACI-N-1-MATEM-TICA-I | C13: SA | D13: Bachiller Común A | E13: COMUNICACIÓN | F13: Nivel 1 | G13: Matemática I | H13: FALSE | I13: TRUE | J13: Troncal | K13: Matemáticas | L13: Formación General
A14: 13 | B14: NES-BACHI-ECONOM-A-Y-ADMI-1-MATEM-TICAS | C14: NES | D14: Bachiller Común A | E14: ECONOMÍA Y ADMINISTRACIÓN | F14: 1 | G14: Matemáticas | H14: FALSE | I14: TRUE | L14: Formación General
A15: 14 | B15: SA-BACHI-ECONOM-A-Y-ADMI-1-MATEM-TICA-I | C15: SA | D15: Bachiller Común A | E15: ECONOMÍA Y ADMINISTRACIÓN | F15: Nivel 1 | G15: Matemática I | H15: FALSE | I15: TRUE | J15: Troncal | K15: Matemáticas | L15: Formación General
A16: 15 | B16: NES-BACHI-EDUCACI-N-1-MATEM-TICAS | C16: NES | D16: Bachiller Común A | E16: EDUCACIÓN | F16: 1 | G16: Matemáticas | H16: FALSE | I16: TRUE | L16: Formación General
A17: 16 | B17: SA-BACHI-EDUCACI-N-1-MATEM-TICA-I | C17: SA | D17: Bachiller Común A | E17: EDUCACIÓN | F17: Nivel 1 | G17: Matemática I | H17: FALSE | I17: TRUE | J17: Troncal | K17: Matemáticas | L17: Formación General
A18: 17 | B18: NES-BACHI-EDUCACI-N-F-SIC-1-MATEM-TICAS | C18: NES | D18: Bachiller Común A | E18: EDUCACIÓN FÍSICA | F18: 1 | G18: Matemáticas | H18: FALSE | I18: TRUE | L18: Formación General
A19: 18 | B19: SA-BACHI-EDUCACI-N-F-SIC-1-MATEM-TICA-I | C19: SA | D19: Bachiller Común A | E19: EDUCACIÓN FÍSICA | F19: Nivel 1 | G19: Matemática I | H19: FALSE | I19: TRUE | J19: Troncal | K19: Matemáticas | L19: Formación General
A20: 19 | B20: NES-BACHI-ENERG-A-Y-SUSTE-1-MATEM-TICAS | C20: NES | D20: Bachiller Común A | E20: ENERGÍA Y SUSTENTABILIDAD | F20: 1 | G20: Matemáticas | H20: FALSE | I20: TRUE | L20: Formación General
A21: 20 | B21: SA-BACHI-ENERG-A-Y-SUSTE-1-MATEM-TICA-I | C21: SA | D21: Bachiller Común A | E21: ENERGÍA Y SUSTENTABILIDAD | F21: Nivel 1 | G21: Matemática I | H21: FALSE | I21: TRUE | J21: Troncal | K21: Matemáticas | L21: Formación General
A22: 21 | B22: NES-BACHI-INFORM-TICA-1-MATEM-TICAS | C22: NES | D22: Bachiller Común A | E22: INFORMÁTICA | F22: 1 | G22: Matemáticas | H22: FALSE | I22: TRUE | L22: Formación General
A23: 22 | B23: SA-BACHI-INFORM-TICA-1-MATEM-TICA-I | C23: SA | D23: Bachiller Común A | E23: INFORMÁTICA | F23: Nivel 1 | G23: Matemática I | H23: FALSE | I23: TRUE | J23: Troncal | K23: Matemáticas | L23: Formación General
A24: 23 | B24: NES-BACHI-LENGUAS-1-MATEM-TICAS | C24: NES | D24: Bachiller Común A | E24: LENGUAS | F24: 1 | G24: Matemáticas | H24: FALSE | I24: TRUE | L24: Formación General
A25: 24 | B25: SA-BACHI-LENGUAS-1-MATEM-TICA-I | C25: SA | D25: Bachiller Común A | E25: LENGUAS | F25: Nivel 1 | G25: Matemática I | H25: FALSE | I25: TRUE | J25: Troncal | K25: Matemáticas | L25: Formación General
A26: 25 | B26: NES-BACHI-LITERATURA-1-MATEM-TICAS | C26: NES | D26: Bachiller Común A | E26: LITERATURA | F26: 1 | G26: Matemáticas | H26: FALSE | I26: TRUE | L26: Formación General
A27: 26 | B27: SA-BACHI-LITERATURA-1-MATEM-TICA-I | C27: SA | D27: Bachiller Común A | E27: LITERATURA | F27: Nivel 1 | G27: Matemática I | H27: FALSE | I27: TRUE | J27: Troncal | K27: Matemáticas | L27: Formación General
A28: 27 | B28: NES-BACHI-MATEM-TICA-Y-F--1-MATEM-TICAS | C28: NES | D28: Bachiller Común A | E28: MATEMÁTICA Y FÍSICA | F28: 1 | G28: Matemáticas | H28: FALSE | I28: TRUE | L28: Formación General
A29: 28 | B29: SA-BACHI-MATEM-TICA-Y-F--1-MATEM-TICA-I | C29: SA | D29: Bachiller Común A | E29: MATEMÁTICA Y FÍSICA | F29: Nivel 1 | G29: Matemática I | H29: FALSE | I29: TRUE | J29: Troncal | K29: Matemáticas | L29: Formación General
A30: 29 | B30: NES-BACHI-TURISMO-1-MATEM-TICAS | C30: NES | D30: Bachiller Común A | E30: TURISMO | F30: 1 | G30: Matemáticas | H30: FALSE | I30: TRUE | L30: Formación General
A31: 30 | B31: SA-BACHI-TURISMO-1-MATEM-TICA-I | C31: SA | D31: Bachiller Común A | E31: TURISMO | F31: Nivel 1 | G31: Matemática I | H31: FALSE | I31: TRUE | J31: Troncal | K31: Matemáticas | L31: Formación General
A32: 31 | B32: NES-BACHI-AGRO-Y-AMBIENTE-1-MATEM-TICAS | C32: NES | D32: Bachiller Común A | E32: AGRO Y AMBIENTE | F32: 1 | G32: Matemáticas | H32: FALSE | I32: TRUE | L32: Formación General
A33: 32 | B33: SA-BACHI-AGRO-Y-AMBIENTE-1-MATEM-TICA-I | C33: SA | D33: Bachiller Común A | E33: AGRO Y AMBIENTE | F33: Nivel 1 | G33: Matemática I | H33: FALSE | I33: TRUE | J33: Troncal | K33: Matemáticas | L33: Formación General
A34: 33 | B34: NES-BACHI-CS-SOCIALES-Y-H-1-LENGUA-Y-LITERATURA | C34: NES | D34: Bachiller Común A | E34: CS. SOCIALES Y HUMANIDADES | F34: 1 | G34: Lengua y Literatura | H34: FALSE | I34: TRUE | L34: Formación Orientada
A35: 34 | B35: SA-BACHI-CS-SOCIALES-Y-H-1-LENGUA-Y-LITERATURA- | C35: SA | D35: Bachiller Común A | E35: CS. SOCIALES Y HUMANIDADES | F35: Nivel 1 | G35: Lengua y Literatura I | H35: FALSE | I35: TRUE | J35: Troncal | K35: Lengua y Literatura | L35: Formación Orientada
A36: 35 | B36: NES-BACHI-ARTES-VISUALES-1-LENGUA-Y-LITERATURA | C36: NES | D36: Bachiller Común A | E36: ARTES VISUALES | F36: 1 | G36: Lengua y Literatura | H36: FALSE | I36: TRUE | L36: Formación Orientada
A37: 36 | B37: SA-BACHI-ARTES-VISUALES-1-LENGUA-Y-LITERATURA- | C37: SA | D37: Bachiller Común A | E37: ARTES VISUALES | F37: Nivel 1 | G37: Lengua y Literatura I | H37: FALSE | I37: TRUE | J37: Troncal | K37: Lengua y Literatura | L37: Formación Orientada
A38: 37 | B38: NES-BACHI-ARTE-MUSICA-1-LENGUA-Y-LITERATURA | C38: NES | D38: Bachiller Común A | E38: ARTE MUSICA | F38: 1 | G38: Lengua y Literatura | H38: FALSE | I38: TRUE | L38: Formación Orientada
A39: 38 | B39: SA-BACHI-ARTE-MUSICA-1-LENGUA-Y-LITERATURA- | C39: SA | D39: Bachiller Común A | E39: ARTE MUSICA | F39: Nivel 1 | G39: Lengua y Literatura I | H39: FALSE | I39: TRUE | J39: Troncal | K39: Lengua y Literatura | L39: Formación Orientada
A40: 39 | B40: NES-BACHI-ARTE-TEATRO-1-LENGUA-Y-LITERATURA | C40: NES | D40: Bachiller Común A | E40: ARTE TEATRO | F40: 1 | G40: Lengua y Literatura | H40: FALSE | I40: TRUE | L40: Formación Orientada
...

Sheet Contenidos_SA_mapeados_GOICE
A1: Contenido_ID | B1: ÁREAS | C1: ESPACIO CURRICULAR | D1: Nivel | E1: Bimestre | F1: Tipo de cursada | G1: TÍTULO DEL PLAN | H1: Enlaces | I1: Columna 9 | J1: Nivel_num | K1: MateriasSA | L1: CategoriaPCI | M1: CategoriaFormacion | N1: Modalidad_Tipo | O1: Especialidades | P1: EsCompuesta | Q1: MateriasNES_Agrupadas | R1: ContenidosPriorizadosID
A2: 1 | B2: Matemática | C2: Matemática | D2: 1 | E2: 1 | F2: Obligatorio | G2: Números naturales y números enteros | J2: 1 | K2: Mat Nivel 1 | Matemática I | L2: Troncal | M2: Formación General | N2: Bachiller Común A | Bachiller Común B | Técnica | O2: AGRO Y AMBIENTE | ARTE MUSICA | ARTE TEATRO | ARTES VISUALES | COMUNICACIÓN | CS. NATURALES | CS. SOCIALES Y HUMANIDADES | ECONOMÍA Y ADMINISTRACIÓN | EDUCACIÓN | EDUCACIÓN FÍSICA | ENERGÍA Y SUSTENTABILIDAD | INFORMÁTICA | LENGUAS | LITERATURA | MATEMÁTICA Y FÍSICA | TURISMO | Técnico AUTOMOTORES | Técnico ELECTRICISTA | Técnico MECÁNICO | Técnico MECÁNICO ELECTRICISTA | P2: Sí | Q2: Matemáticas
A3: 2 | B3: Matemática | C3: Matemática | D3: 1 | E3: 2 | F3: Obligatorio | G3: Gráficos cartesianos | J3: 1 | K3: Mat Nivel 1 | Matemática I | L3: Troncal | M3: Formación General | N3: Bachiller Común A | Bachiller Común B | Técnica | O3: AGRO Y AMBIENTE | ARTE MUSICA | ARTE TEATRO | ARTES VISUALES | COMUNICACIÓN | CS. NATURALES | CS. SOCIALES Y HUMANIDADES | ECONOMÍA Y ADMINISTRACIÓN | EDUCACIÓN | EDUCACIÓN FÍSICA | ENERGÍA Y SUSTENTABILIDAD | INFORMÁTICA | LENGUAS | LITERATURA | MATEMÁTICA Y FÍSICA | TURISMO | Técnico AUTOMOTORES | Técnico ELECTRICISTA | Técnico MECÁNICO | Técnico MECÁNICO ELECTRICISTA | P3: Sí | Q3: Matemáticas
A4: 3 | B4: Matemática | C4: Matemática | D4: 1 | E4: 3 | F4: Obligatorio | G4: Triángulos | J4: 1 | K4: Mat Nivel 1 | Matemática I | L4: Troncal | M4: Formación General | N4: Bachiller Común A | Bachiller Común B | Técnica | O4: AGRO Y AMBIENTE | ARTE MUSICA | ARTE TEATRO | ARTES VISUALES | COMUNICACIÓN | CS. NATURALES | CS. SOCIALES Y HUMANIDADES | ECONOMÍA Y ADMINISTRACIÓN | EDUCACIÓN | EDUCACIÓN FÍSICA | ENERGÍA Y SUSTENTABILIDAD | INFORMÁTICA | LENGUAS | LITERATURA | MATEMÁTICA Y FÍSICA | TURISMO | Técnico AUTOMOTORES | Técnico ELECTRICISTA | Técnico MECÁNICO | Técnico MECÁNICO ELECTRICISTA | P4: Sí | Q4: Matemáticas
A5: 4 | B5: Matemática | C5: Matemática | D5: 1 | E5: 4 | F5: Obligatorio | G5: Estadística | J5: 1 | K5: Mat Nivel 1 | Matemática I | L5: Troncal | M5: Formación General | N5: Bachiller Común A | Bachiller Común B | Técnica | O5: AGRO Y AMBIENTE | ARTE MUSICA | ARTE TEATRO | ARTES VISUALES | COMUNICACIÓN | CS. NATURALES | CS. SOCIALES Y HUMANIDADES | ECONOMÍA Y ADMINISTRACIÓN | EDUCACIÓN | EDUCACIÓN FÍSICA | ENERGÍA Y SUSTENTABILIDAD | INFORMÁTICA | LENGUAS | LITERATURA | MATEMÁTICA Y FÍSICA | TURISMO | Técnico AUTOMOTORES | Técnico ELECTRICISTA | Técnico MECÁNICO | Técnico MECÁNICO ELECTRICISTA | P5: Sí | Q5: Matemáticas
A6: 5 | B6: Matemática | C6: Matemática | D6: 2 | E6: 1 | F6: Obligatorio | G6: Divisibilidad | J6: 2 | K6: Mat Nivel 2 | Matemática II | L6: Troncal | M6: Formación General | N6: Bachiller Común A | Bachiller Común B | Técnica | O6: AGRO Y AMBIENTE | ARTE MUSICA | ARTE TEATRO | ARTES VISUALES | COMUNICACIÓN | CS. NATURALES | CS. SOCIALES Y HUMANIDADES | ECONOMÍA Y ADMINISTRACIÓN | EDUCACIÓN | EDUCACIÓN FÍSICA | ENERGÍA Y SUSTENTABILIDAD | INFORMÁTICA | LENGUAS | LITERATURA | MATEMÁTICA Y FÍSICA | TURISMO | Técnico AUTOMOTORES | Técnico ELECTRICISTA | Técnico MECÁNICO | Técnico MECÁNICO ELECTRICISTA | P6: Sí | Q6: Matemáticas
A7: 6 | B7: Matemática | C7: Matemática | D7: 2 | E7: 2 | F7: Obligatorio | G7: Función lineal | J7: 2 | K7: Mat Nivel 2 | Matemática II | L7: Troncal | M7: Formación General | N7: Bachiller Común A | Bachiller Común B | Técnica | O7: AGRO Y AMBIENTE | ARTE MUSICA | ARTE TEATRO | ARTES VISUALES | COMUNICACIÓN | CS. NATURALES | CS. SOCIALES Y HUMANIDADES | ECONOMÍA Y ADMINISTRACIÓN | EDUCACIÓN | EDUCACIÓN FÍSICA | ENERGÍA Y SUSTENTABILIDAD | INFORMÁTICA | LENGUAS | LITERATURA | MATEMÁTICA Y FÍSICA | TURISMO | Técnico AUTOMOTORES | Técnico ELECTRICISTA | Técnico MECÁNICO | Técnico MECÁNICO ELECTRICISTA | P7: Sí | Q7: Matemáticas
A8: 7 | B8: Matemática | C8: Matemática | D8: 2 | E8: 3 | F8: Obligatorio | G8: Cuadriláteros y Teorema de Thales | J8: 2 | K8: Mat Nivel 2 | Matemática II | L8: Troncal | M8: Formación General | N8: Bachiller Común A | Bachiller Común B | Técnica | O8: AGRO Y AMBIENTE | ARTE MUSICA | ARTE TEATRO | ARTES VISUALES | COMUNICACIÓN | CS. NATURALES | CS. SOCIALES Y HUMANIDADES | ECONOMÍA Y ADMINISTRACIÓN | EDUCACIÓN | EDUCACIÓN FÍSICA | ENERGÍA Y SUSTENTABILIDAD | INFORMÁTICA | LENGUAS | LITERATURA | MATEMÁTICA Y FÍSICA | TURISMO | Técnico AUTOMOTORES | Técnico ELECTRICISTA | Técnico MECÁNICO | Técnico MECÁNICO ELECTRICISTA | P8: Sí | Q8: Matemáticas
A9: 8 | B9: Matemática | C9: Matemática | D9: 2 | E9: 4 | F9: Obligatorio | G9: Estadística | J9: 2 | K9: Mat Nivel 2 | Matemática II | L9: Troncal | M9: Formación General | N9: Bachiller Común A | Bachiller Común B | Técnica | O9: AGRO Y AMBIENTE | ARTE MUSICA | ARTE TEATRO | ARTES VISUALES | COMUNICACIÓN | CS. NATURALES | CS. SOCIALES Y HUMANIDADES | ECONOMÍA Y ADMINISTRACIÓN | EDUCACIÓN | EDUCACIÓN FÍSICA | ENERGÍA Y SUSTENTABILIDAD | INFORMÁTICA | LENGUAS | LITERATURA | MATEMÁTICA Y FÍSICA | TURISMO | Técnico AUTOMOTORES | Técnico ELECTRICISTA | Técnico MECÁNICO | Técnico MECÁNICO ELECTRICISTA | P9: Sí | Q9: Matemáticas
A10: 9 | B10: Matemática | C10: Matemática | D10: 3 | E10: 1 | F10: Obligatorio | G10: Problemas de conteo | J10: 3 | K10: Mat Nivel 3 | Matemática III | Taller de la Especialidad | L10: Troncal | M10: Formación General | N10: Bachiller Común A | Bachiller Común B | Técnica | O10: AGRO Y AMBIENTE | ARTE MUSICA | ARTE TEATRO | ARTES VISUALES | COMUNICACIÓN | CS. NATURALES | CS. SOCIALES Y HUMANIDADES | ECONOMÍA Y ADMINISTRACIÓN | EDUCACIÓN | EDUCACIÓN FÍSICA | ENERGÍA Y SUSTENTABILIDAD | INFORMÁTICA | LENGUAS | LITERATURA | MATEMÁTICA Y FÍSICA | TURISMO | Técnico AUTOMOTORES | Técnico ELECTRICISTA | Técnico MECÁNICO | Técnico MECÁNICO ELECTRICISTA | P10: Sí | Q10: Matemática || Matemáticas || Taller de Tecnología y Control; Taller de Geografía Matemática
A11: 10 | B11: Matemática | C11: Matemática | D11: 3 | E11: 2 | F11: Obligatorio | G11: Sistema de ecuaciones | J11: 3 | K11: Mat Nivel 3 | Matemática III | Taller de la Especialidad | L11: Troncal | M11: Formación General | N11: Bachiller Común A | Bachiller Común B | Técnica | O11: AGRO Y AMBIENTE | ARTE MUSICA | ARTE TEATRO | ARTES VISUALES | COMUNICACIÓN | CS. NATURALES | CS. SOCIALES Y HUMANIDADES | ECONOMÍA Y ADMINISTRACIÓN | EDUCACIÓN | EDUCACIÓN FÍSICA | ENERGÍA Y SUSTENTABILIDAD | INFORMÁTICA | LENGUAS | LITERATURA | MATEMÁTICA Y FÍSICA | TURISMO | Técnico AUTOMOTORES | Técnico ELECTRICISTA | Técnico MECÁNICO | Técnico MECÁNICO ELECTRICISTA | P11: Sí | Q11: Matemática || Matemáticas || Taller de Tecnología y Control; Taller de Geografía Matemática
A12: 11 | B12: Matemática | C12: Matemática | D12: 3 | E12: 3 | F12: Obligatorio | G12: Razones trigonométricas | J12: 3 | K12: Mat Nivel 3 | Matemática III | Taller de la Especialidad | L12: Troncal | M12: Formación General | N12: Bachiller Común A | Bachiller Común B | Técnica | O12: AGRO Y AMBIENTE | ARTE MUSICA | ARTE TEATRO | ARTES VISUALES | COMUNICACIÓN | CS. NATURALES | CS. SOCIALES Y HUMANIDADES | ECONOMÍA Y ADMINISTRACIÓN | EDUCACIÓN | EDUCACIÓN FÍSICA | ENERGÍA Y SUSTENTABILIDAD | INFORMÁTICA | LENGUAS | LITERATURA | MATEMÁTICA Y FÍSICA | TURISMO | Técnico AUTOMOTORES | Técnico ELECTRICISTA | Técnico MECÁNICO | Técnico MECÁNICO ELECTRICISTA | P12: Sí | Q12: Matemática || Matemáticas || Taller de Tecnología y Control; Taller de Geografía Matemática
A13: 12 | B13: Matemática | C13: Matemática | D13: 3 | E13: 4 | F13: Obligatorio | G13: Función cuadrática | J13: 3 | K13: Mat Nivel 3 | Matemática III | Taller de la Especialidad | L13: Troncal | M13: Formación General | N13: Bachiller Común A | Bachiller Común B | Técnica | O13: AGRO Y AMBIENTE | ARTE MUSICA | ARTE TEATRO | ARTES VISUALES | COMUNICACIÓN | CS. NATURALES | CS. SOCIALES Y HUMANIDADES | ECONOMÍA Y ADMINISTRACIÓN | EDUCACIÓN | EDUCACIÓN FÍSICA | ENERGÍA Y SUSTENTABILIDAD | INFORMÁTICA | LENGUAS | LITERATURA | MATEMÁTICA Y FÍSICA | TURISMO | Técnico AUTOMOTORES | Técnico ELECTRICISTA | Técnico MECÁNICO | Técnico MECÁNICO ELECTRICISTA | P13: Sí | Q13: Matemática || Matemáticas || Taller de Tecnología y Control; Taller de Geografía Matemática
... A143: 142 | B143: Ciencias Naturales | C143: Cs. naturales | D143: 5 | E143: 4 | F143: Electivo | G143: Del ADN a tu plato B | J143: 5 | K143: Laboratorio Ciencias Naturales I | L143: Laboratorio | M143: Formación Orientada | N143: Bachiller Común A | Bachiller Común B | O143: AGRO Y AMBIENTE | ARTE MUSICA | ARTE TEATRO | ARTES VISUALES | COMUNICACIÓN | CS. NATURALES | CS. SOCIALES Y HUMANIDADES | ECONOMÍA Y ADMINISTRACIÓN | EDUCACIÓN | EDUCACIÓN FÍSICA | ENERGÍA Y SUSTENTABILIDAD | INFORMÁTICA | LENGUAS | LITERATURA | MATEMÁTICA Y FÍSICA | TURISMO | P143: Sí | Q143: Química
A144: 143 | B144: Proyecto | C144: Plan Bimestral_ Bases de la Gestión de Proyectos.docx | D144: 45813 | E144: 1 | F144: Obligatorio | G144: Base de la gestión de proyectos BO | L144: Troncal
A145: 144 | B145: Proyecto | C145: Plan Bimestral_ Bases de la Gestión de Proyectos - TÉCNICAS.docx | D145: 6 | E145: 1 | F145: Obligatorio | G145: Base de la gestión de proyectos Técnicas | J145: 6 | L145: Troncal
A146: 145 | B146: Arte | C146: Artes | D146: 1 | E146: 1 | F146: Electivo | G146: El cuerpo y la actitud corporal | J146: 1 | K146: Taller de Artes A + B | L146: Taller | M146: Formación General | N146: Bachiller Común A | Bachiller Común B | O146: AGRO Y AMBIENTE | ARTE MUSICA | ARTE TEATRO | ARTES VISUALES | COMUNICACIÓN | CS. NATURALES | CS. SOCIALES Y HUMANIDADES | ECONOMÍA Y ADMINISTRACIÓN | EDUCACIÓN | EDUCACIÓN FÍSICA | ENERGÍA Y SUSTENTABILIDAD | INFORMÁTICA | LENGUAS | LITERATURA | MATEMÁTICA Y FÍSICA | TURISMO | P146: Sí | Q146: Artes; EDI; Tutoría
A147: 146 | B147: Arte | C147: Artes | D147: 1 | E147: 2 | F147: Electivo | G147: La acción, conflicto y desenlace | J147: 1 | K147: Taller de Artes A + B | L147: Taller | M147: Formación General | N147: Bachiller Común A | Bachiller Común B | O147: AGRO Y AMBIENTE | ARTE MUSICA | ARTE TEATRO | ARTES VISUALES | COMUNICACIÓN | CS. NATURALES | CS. SOCIALES Y HUMANIDADES | ECONOMÍA Y ADMINISTRACIÓN | EDUCACIÓN | EDUCACIÓN FÍSICA | ENERGÍA Y SUSTENTABILIDAD | INFORMÁTICA | LENGUAS | LITERATURA | MATEMÁTICA Y FÍSICA | TURISMO | P147: Sí | Q147: Artes; EDI; Tutoría
A148: 147 | B148: Arte | C148: Artes | D148: 1 | E148: 3 | F148: Electivo | G148: Modelos, letras y música | J148: 1 | K148: Taller de Artes A + B | L148: Taller | M148: Formación General | N148: Bachiller Común A | Bachiller Común B | O148: AGRO Y AMBIENTE | ARTE MUSICA | ARTE TEATRO | ARTES VISUALES | COMUNICACIÓN | CS. NATURALES | CS. SOCIALES Y HUMANIDADES | ECONOMÍA Y ADMINISTRACIÓN | EDUCACIÓN | EDUCACIÓN FÍSICA | ENERGÍA Y SUSTENTABILIDAD | INFORMÁTICA | LENGUAS | LITERATURA | MATEMÁTICA Y FÍSICA | TURISMO | P148: Sí | Q148: Artes; EDI; Tutoría
A149: 148 | B149: Arte | C149: Artes | D149: 1 | E149: 4 | F149: Electivo | G149: Música: Características musicales | J149: 1 | K149: Taller de Artes A + B | L149: Taller | M149: Formación General | N149: Bachiller Común A | Bachiller Común B | O149: AGRO Y AMBIENTE | ARTE MUSICA | ARTE TEATRO | ARTES VISUALES | COMUNICACIÓN | CS. NATURALES | CS. SOCIALES Y HUMANIDADES | ECONOMÍA Y ADMINISTRACIÓN | EDUCACIÓN | EDUCACIÓN FÍSICA | ENERGÍA Y SUSTENTABILIDAD | INFORMÁTICA | LENGUAS | LITERATURA | MATEMÁTICA Y FÍSICA | TURISMO | P149: Sí | Q149: Artes; EDI; Tutoría
A150: 149 | B150: Arte | C150: Artes | D150: 2 | E150: 1 | F150: Electivo | G150: Quién es quién: Fantasías, realismos y ficciones: Reproducción y matriz | J150: 2 | K150: Taller de Artes C + D | L150: Taller | M150: Formación General | N150: Bachiller Común A | Bachiller Común B | O150: AGRO Y AMBIENTE | ARTE MUSICA | ARTE TEATRO | ARTES VISUALES | COMUNICACIÓN | CS. NATURALES | CS. SOCIALES Y HUMANIDADES | ECONOMÍA Y ADMINISTRACIÓN | EDUCACIÓN | EDUCACIÓN FÍSICA | ENERGÍA Y SUSTENTABILIDAD | INFORMÁTICA | LENGUAS | LITERATURA | MATEMÁTICA Y FÍSICA | TURISMO | P150: Sí | Q150: Artes; EDI; Tutoría
A151: 150 | B151: Arte | C151: Artes | D151: 2 | E151: 2 | F151: Electivo | G151: Quién es quién: Fantasías, realismos y ficciones: Arte moderno latinoamericano | J151: 2 | K151: Taller de Artes C + D | L151: Taller | M151: Formación General | N151: Bachiller Común A | Bachiller Común B | O151: AGRO Y AMBIENTE | ARTE MUSICA | ARTE TEATRO | ARTES VISUALES | COMUNICACIÓN | CS. NATURALES | CS. SOCIALES Y HUMANIDADES | ECONOMÍA Y ADMINISTRACIÓN | EDUCACIÓN | EDUCACIÓN FÍSICA | ENERGÍA Y SUSTENTABILIDAD | INFORMÁTICA | LENGUAS | LITERATURA | MATEMÁTICA Y FÍSICA | TURISMO | P151: Sí | Q151: Artes; EDI; Tutoría
A152: 151 | B152: Arte | C152: Artes | D152: 2 | E152: 1 | F152: Electivo | G152: El territorio cotidiano: Conceptos claves | J152: 2 | K152: Taller de Artes C + D | L152: Taller | M152: Formación General | N152: Bachiller Común A | Bachiller Común B | O152: AGRO Y AMBIENTE | ARTE MUSICA | ARTE TEATRO | ARTES VISUALES | COMUNICACIÓN | CS. NATURALES | CS. SOCIALES Y HUMANIDADES | ECONOMÍA Y ADMINISTRACIÓN | EDUCACIÓN | EDUCACIÓN FÍSICA | ENERGÍA Y SUSTENTABILIDAD | INFORMÁTICA | LENGUAS | LITERATURA | MATEMÁTICA Y FÍSICA | TURISMO | P152: Sí | Q152: Artes; EDI; Tutoría
A153: 152 | B153: Arte | C153: Artes | D153: 2 | E153: 3 | F153: Electivo | G153: El territorio cotidiano: El objeto como obra de arte | J153: 2 | K153: Taller de Artes C + D | L153: Taller | M153: Formación General | N153: Bachiller Común A | Bachiller Común B | O153: AGRO Y AMBIENTE | ARTE MUSICA | ARTE TEATRO | ARTES VISUALES | COMUNICACIÓN | CS. NATURALES | CS. SOCIALES Y HUMANIDADES | ECONOMÍA Y ADMINISTRACIÓN | EDUCACIÓN | EDUCACIÓN FÍSICA | ENERGÍA Y SUSTENTABILIDAD | INFORMÁTICA | LENGUAS | LITERATURA | MATEMÁTICA Y FÍSICA | TURISMO | P153: Sí | Q153: Artes; EDI; Tutoría
A154: 153 | B154: Arte | C154: Artes | D154: 2 | E154: 4 | F154: Electivo | G154: Música: La voz | J154: 2 | K154: Taller de Artes C + D | L154: Taller | M154: Formación General | N154: Bachiller Común A | Bachiller Común B | O154: AGRO Y AMBIENTE | ARTE MUSICA | ARTE TEATRO | ARTES VISUALES | COMUNICACIÓN | CS. NATURALES | CS. SOCIALES Y HUMANIDADES | ECONOMÍA Y ADMINISTRACIÓN | EDUCACIÓN | EDUCACIÓN FÍSICA | ENERGÍA Y SUSTENTABILIDAD | INFORMÁTICA | LENGUAS | LITERATURA | MATEMÁTICA Y FÍSICA | TURISMO | P154: Sí | Q154: Artes; EDI; Tutoría
